<?xml version="1.0"?>
<robot name="robopostman">

  <!-- BASE LINK -->
  <link name="base_link">
    <visual>
      <geometry><box size="0.5 0.3 0.15"/></geometry>
      <material name="blue"><color rgba="0.0 0.0 0.8 1.0"/></material>
    </visual>
    <collision>
      <geometry><box size="0.5 0.3 0.15"/></geometry>
    </collision>
    <inertial>
      <mass value="5.0"/>
      <inertia ixx="0.1" ixy="0.0" ixz="0.0" iyy="0.1" iyz="0.0" izz="0.1"/>
    </inertial>
  </link>

  <!-- BASE FOOTPRINT -->
  <link name="base_footprint"/>
  <joint name="base_footprint_joint" type="fixed">
    <parent link="base_footprint"/>
    <child link="base_link"/>
    <origin xyz="0 0 0.1" rpy="0 0 0"/>
  </joint>

  <!-- LIDAR LINK -->
  <link name="laser">
    <visual>
      <geometry><cylinder radius="0.04" length="0.05"/></geometry>
      <material name="black"><color rgba="0.0 0.0 0.0 1.0"/></material>
    </visual>
    <collision>
      <geometry><cylinder radius="0.04" length="0.05"/></geometry>
    </collision>
    <inertial>
      <mass value="0.1"/>
      <inertia ixx="0.001" ixy="0.0" ixz="0.0" iyy="0.001" iyz="0.0" izz="0.001"/>
    </inertial>
  </link>
  <joint name="laser_joint" type="fixed">
    <parent link="base_link"/>
    <child link="laser"/>
    <origin xyz="0.2 0 0.1" rpy="0 0 0"/>
  </joint>

  <!-- CAMERA LINK -->
  <link name="camera_link">
    <visual>
      <geometry><box size="0.04 0.08 0.04"/></geometry>
      <material name="grey"><color rgba="0.5 0.5 0.5 1.0"/></material>
    </visual>
    <inertial>
      <mass value="0.05"/>
      <inertia ixx="0.001" ixy="0.0" ixz="0.0" iyy="0.001" iyz="0.0" izz="0.001"/>
    </inertial>
  </link>
  <joint name="camera_joint" type="fixed">
    <parent link="base_link"/>
    <child link="camera_link"/>
    <origin xyz="0.25 0 0.08" rpy="0 0 0"/>
  </joint>

  <!-- LEFT WHEEL -->
  <link name="left_wheel">
    <visual>
      <geometry><cylinder radius="0.08" length="0.04"/></geometry>
      <material name="dark"><color rgba="0.1 0.1 0.1 1.0"/></material>
    </visual>
    <collision>
      <geometry><cylinder radius="0.08" length="0.04"/></geometry>
    </collision>
    <inertial>
      <mass value="0.5"/>
      <inertia ixx="0.01" ixy="0.0" ixz="0.0" iyy="0.01" iyz="0.0" izz="0.01"/>
    </inertial>
  </link>
  <joint name="left_wheel_joint" type="continuous">
    <parent link="base_link"/>
    <child link="left_wheel"/>
    <origin xyz="0 0.17 -0.02" rpy="-1.5707963 0 0"/>
    <axis xyz="0 0 1"/>
  </joint>

  <!-- RIGHT WHEEL -->
  <link name="right_wheel">
    <visual>
      <geometry><cylinder radius="0.08" length="0.04"/></geometry>
      <material name="dark"><color rgba="0.1 0.1 0.1 1.0"/></material>
    </visual>
    <collision>
      <geometry><cylinder radius="0.08" length="0.04"/></geometry>
    </collision>
    <inertial>
      <mass value="0.5"/>
      <inertia ixx="0.01" ixy="0.0" ixz="0.0" iyy="0.01" iyz="0.0" izz="0.01"/>
    </inertial>
  </link>
  <joint name="right_wheel_joint" type="continuous">
    <parent link="base_link"/>
    <child link="right_wheel"/>
    <origin xyz="0 -0.17 -0.02" rpy="-1.5707963 0 0"/>
    <axis xyz="0 0 1"/>
  </joint>

  <!-- CASTER WHEEL -->
  <link name="caster_wheel">
    <visual><geometry><sphere radius="0.04"/></geometry></visual>
    <collision><geometry><sphere radius="0.04"/></geometry></collision>
    <inertial>
      <mass value="0.1"/>
      <inertia ixx="0.001" ixy="0.0" ixz="0.0" iyy="0.001" iyz="0.0" izz="0.001"/>
    </inertial>
  </link>
  <joint name="caster_joint" type="fixed">
    <parent link="base_link"/>
    <child link="caster_wheel"/>
    <origin xyz="-0.2 0 -0.06" rpy="0 0 0"/>
  </joint>

  <!-- DIFF DRIVE PLUGIN -->
  <gazebo>
    <plugin filename="gz-sim-diff-drive-system"
            name="gz::sim::systems::DiffDrive">
      <left_joint>left_wheel_joint</left_joint>
      <right_joint>right_wheel_joint</right_joint>
      <wheel_separation>0.34</wheel_separation>
      <wheel_radius>0.08</wheel_radius>
      <max_linear_acceleration>1.0</max_linear_acceleration>
      <max_angular_acceleration>2.0</max_angular_acceleration>
      <max_linear_velocity>0.5</max_linear_velocity>
      <max_angular_velocity>1.0</max_angular_velocity>
      <topic>/cmd_vel</topic>
      <odom_topic>/odom</odom_topic>
      <tf_topic>/tf</tf_topic>
      <frame_id>odom</frame_id>
      <child_frame_id>base_footprint</child_frame_id>
      <odom_publish_frequency>50</odom_publish_frequency>
    </plugin>
  </gazebo>

  <!-- LIDAR SENSOR -->
  <gazebo reference="laser">
    <sensor name="lidar" type="gpu_lidar">
      <always_on>true</always_on>
      <visualize>false</visualize>
      <update_rate>10</update_rate>
      <topic>/scan</topic>
      <gz_frame_id>laser</gz_frame_id>
      <lidar>
        <scan>
          <horizontal>
            <samples>360</samples>
            <resolution>1</resolution>
            <min_angle>-3.14159</min_angle>
            <max_angle>3.14159</max_angle>
          </horizontal>
        </scan>
        <range>
          <min>0.12</min>
          <max>10.0</max>
          <resolution>0.015</resolution>
        </range>
        <noise>
          <type>gaussian</type>
          <mean>0.0</mean>
          <stddev>0.01</stddev>
        </noise>
      </lidar>
    </sensor>
  </gazebo>

  <!-- CAMERA SENSOR -->
  <gazebo reference="camera_link">
    <sensor name="camera" type="camera">
      <always_on>true</always_on>
      <visualize>true</visualize>
      <update_rate>10</update_rate>
      <topic>/camera/image_raw</topic>
      <gz_frame_id>camera_link</gz_frame_id>
      <camera>
        <horizontal_fov>1.3962634</horizontal_fov>
        <image>
          <width>320</width>
          <height>240</height>
          <format>R8G8B8</format>
        </image>
        <clip>
          <near>0.02</near>
          <far>300</far>
        </clip>
      </camera>
    </sensor>
  </gazebo>

</robot>
